<?xml version="1.0"?>
<robot name="Leftarmchain">

<material name="blue">
    <color rgba="0 0 0.8 1"/>
  </material>
  <material name="black">
    <color rgba="0 0 0 1"/>
  </material>
  <material name="orange">
    <color rgba="0.8 0.2 0 1"/>
  </material>
  <material name="green">
    <color rgba="0 1 0 1"/>
  </material>
  <material name="white">
    <color rgba="1 1 1 1"/>
  </material>


  <link name="base_link">
    <visual>
      <geometry>
        <box size="0.2 1.2 0.2"/>
      </geometry>
      <material name="blue"/>
    </visual>
  </link>

  

  <link name="pitch_shoulder"/>
  <joint name="pitch_shoulder" type="revolute">
    <axis xyz="0 0 1"/>
    <limit effort="1000.0" lower="0.0" upper="0.548" velocity="0.5"/> 
    <origin rpy="1.5707 0 3.1415" xyz="0 -0.6 0"/>
    <parent link="base_link"/>
    <child link="pitch_shoulder"/>
  </joint>

  <link name="roll_shoulder"/>
  <joint name="roll_shoulder" type="revolute">
    <axis xyz="0 0 1"/>
    <limit effort="1000.0" lower="0.0" upper="0.548" velocity="0.5"/> 
    <origin rpy="1.5707 0 -1.5707" xyz="0 0 0"/>
    <parent link="pitch_shoulder"/>
    <child link="roll_shoulder"/>
  </joint>

  <link name="yaw_shoulder"/>
  <joint name="yaw_shoulder" type="revolute">
    <axis xyz="0 0 1"/>
    <limit effort="1000.0" lower="0.0" upper="0.548" velocity="0.5"/> 
    <origin rpy="1.5707 0 1.5707" xyz="0 0 0"/>
    <parent link="roll_shoulder"/>
    <child link="yaw_shoulder"/>
  </joint>

  <link name="biceps">
    <visual>
      <origin xyz="0 0 0.4" rpy="0 0 0"></origin>
      <geometry>
        <box size ="0.2 0.2 0.8"/>
      </geometry>
      <material name="white"/>
    </visual>
  </link>

  <joint name="biceps" type="fixed">
    <origin rpy="0 0 0" xyz="0 0 0"/>
    <parent link="yaw_shoulder"/>
    <child link="biceps"/>
  </joint>

  <link name="arm">
    <visual>
      <origin xyz="0 .3 0" rpy="0 0 0"></origin>
      <geometry>
        <box size ="0.2 0.6 0.2"/>
      </geometry>
      <material name="blue"/>
    </visual>
  </link>


   <joint name="pitch_elbow" type="revolute">
    <axis xyz="0 0 1"/>
    <limit effort="1000.0" lower="0.0" upper="0.548" velocity="0.5"/> 
    <origin rpy="1.5707 0 -1.5707" xyz="0 0 0.8"/>
    <parent link="biceps"/>
    <child link="arm"/>
  </joint> 

  <link name="hand">
    <visual>
      <origin xyz="0 0 0" rpy="0 0 0"></origin>
      <geometry>
        <sphere  radius ="0.2"/>
      </geometry>
      <material name="green"/>
    </visual>
  </link>

  <joint name="wrist" type="fixed">
    <origin rpy="0 0 0" xyz="0 0.6 0"/>
    <parent link="arm"/>
    <child link="hand"/>
  </joint>  

</robot>

