<?xml version="1.0"?>
<robot name="Leftarmchain">

<material name="blue">
    <color rgba="0 0 0.8 1"/>
  </material>
  <material name="black">
    <color rgba="0 0 0 1"/>
  </material>
  <material name="orange">
    <color rgba="0.8 0.2 0 1"/>
  </material>
  <material name="green">
    <color rgba="0 1 0 1"/>
  </material>
  <material name="white">
    <color rgba="1 1 1 1"/>
  </material>

<link name="base_link">
    <visual>
      <geometry>
        <box size="0.2 1.2 0.2"/>
      </geometry>
      <material name="blue"/>
    </visual>
  </link>



<link name="roll_hip"/>
  <joint name="roll_hip" type="revolute">
    <axis xyz="0 0 1"/>
    <limit effort="1000.0" lower="0.0" upper="0.548" velocity="0.5"/> 
    <origin rpy="1.5707 0 1.5707" xyz="0 -0.6 0"/>
    <parent link="base_link"/>
    <child link="roll_hip"/>
  </joint>

<link name="pitch_hip"/>
  <joint name="pitch_hip" type="revolute">
    <axis xyz="0 0 1"/>
    <limit effort="1000.0" lower="0.0" upper="0.548" velocity="0.5"/> 
    <origin rpy="1.5707 0 -1.5707" xyz="0 0 0"/>
    <parent link="roll_hip"/>
    <child link="pitch_hip"/>
  </joint>

  <link name="tibia">
    <visual>
      <origin xyz="0.4 0 0" rpy="0 0 0"></origin>
      <geometry>
        <box size ="0.8 0.2 0.2"/>
      </geometry>
      <material name="white"/>
    </visual>
  </link>

<joint name="tibia" type="fixed">
    <origin rpy="0 0 0" xyz="0 0 0"/>
    <parent link="pitch_hip"/>
    <child link="tibia"/>
</joint> 


<link name="calf">
    <visual>
      <origin xyz="0.3 0 0" rpy="0 0 0"></origin>
      <geometry>
        <box size ="0.6 0.2 0.2"/>
      </geometry>
      <material name="blue"/>
    </visual>
</link>

<joint name="pitch_knee" type="revolute">
    <axis xyz="0 0 1"/>
    <limit effort="1000.0" lower="0.0" upper="0.548" velocity="0.5"/> 
    <origin rpy="0 0 0" xyz="0.8 0 0"/>
    <parent link="tibia"/>
    <child link="calf"/>
  </joint> 

<link name="ankle">
    <visual>
      <origin xyz="0 0 0" rpy="0 0 0"></origin>
      <geometry>
        <sphere  radius ="0.2"/>
      </geometry>
      <material name="green"/>
    </visual>
</link>  


<joint name="ankle_joint" type="fixed">
    <origin rpy="0 0 0" xyz="0.6 0 0"/>
    <parent link="calf"/>
    <child link="ankle"/>
</joint> 

</robot>