<?xml version="1.0"?>
<robot name="legchain">


<material name="blue">
    <color rgba="0 0 0.8 1"/>
  </material>
  <material name="black">
    <color rgba="0 0 0 1"/>
  </material>
  <material name="orange">
    <color rgba="0.8 0.2 0 1"/>
  </material>
  <material name="green">
    <color rgba="0 1 0 1"/>
  </material>
  <material name="white">
    <color rgba="1 1 1 1"/>
  </material>


  <link name="base_link">
    <visual>
      <geometry>
        <box size="0.2 0.6 0.6"/>
      </geometry>
      <material name="blue"/>
    </visual>
  </link>

  <link name="link_1">
    <visual>
      <origin xyz="-0.6 0 0" rpy="0 1.5707 0"></origin>
      <geometry>
        <cylinder length="1.2" radius="0.2"/>
      </geometry>
      <material name="white"/>
    </visual>
  </link>

  <joint name="roll1" type="revolute">
    <axis xyz="0 0 1"/>
    <limit effort="1000.0" lower="-3.1415" upper="0.0" velocity="0.5"/> 
    <origin rpy="1.5707 0 3.1415" xyz="0 0 0.3"/>
    <parent link="base_link"/>
    <child link="link_1"/>
  </joint>

   <link name="link_2">
    <visual>
      <origin xyz="-0.6 0 0" rpy="0 1.5707 0"></origin>
      <geometry>
        <cylinder length="1.2" radius="0.2"/>
      </geometry>
      <material name="white"/>
    </visual>
  </link>
   

  
  <joint name="roll2" type="revolute">
    <axis xyz="0 0 1"/>
    <limit effort="1000.0" lower="-1.5707" upper="1.5707" velocity="0.5"/> 
    <origin rpy="0 0 0" xyz="-1.2 0 0"/>
    <parent link="link_1"/>
    <child link="link_2"/>
  </joint>

  <link name="end_1">
    <visual>
      <geometry>
        <sphere radius="0.2"/>
      </geometry>
      <material name="orange"/>
    </visual>
  </link>

  <joint name="end1" type="fixed">
    <origin rpy="0 0 0" xyz="-1.2 0 0"/>
    <parent link="link_2"/>
    <child link="end_1"/>
  </joint>

</robot>
